Workbook

Sheet map
A1: id | B1: platform | C1: label | D1: pathway_group | E1: pathway | F1: subpathway | G1: liu_name | H1: julkunen_name | I1: bbs_name | J1: direct_name | K1: ukbb_olink_name | L1: gwas_name | M1: gwas_id | N1: bbs_pathway | O1: direct_pathway | P1: bbs_subpathway | Q1: direct_subpathway | R1: gwas_pathway | S1: gwas_subpathway
A2: metab_compid_57814 | B2: metabolon | C2: (N(1) + N(8))-acetylspermidine | D2: =_xlfn.XLOOKUP(E2,pathways!$A$2:$A$31,pathways!$B$2:$B$31) -> Amino acid metabolism | E2: Amino Acid | F2: Polyamine Metabolism | G2: (N(1) + N(8))-acetylspermidine | I2: (N(1) + N(8))-acetylspermidine | J2: (N(1) + N(8))-acetylspermidine | L2: (N(1) + N(8))-acetylspermidine levels | M2: GCST90200153 | N2: Amino Acid | O2: Amino Acid | P2: Polyamine Metabolism | Q2: Polyamine Metabolism | R2: Amino Acid
A3: metab_compid_32350 | B3: metabolon | C3: 1-methyl-4-imidazoleacetate | D3: =_xlfn.XLOOKUP(E3,pathways!$A$2:$A$31,pathways!$B$2:$B$31) -> Amino acid metabolism | E3: Amino Acid | F3: Histidine Metabolism | G3: 1-methyl-4-imidazoleacetate | I3: 1-methyl-4-imidazoleacetate | J3: 1-methyl-4-imidazoleacetate | L3: 1-methyl-4-imidazoleacetate levels | M3: GCST90199717 | N3: Amino Acid | O3: Amino Acid | P3: Histidine Metabolism | Q3: Histidine Metabolism | R3: Amino Acid
A4: metab_compid_62946 | B4: metabolon | C4: 1-methyl-5-imidazoleacetate | D4: =_xlfn.XLOOKUP(E4,pathways!$A$2:$A$31,pathways!$B$2:$B$31) -> Amino acid metabolism | E4: Amino Acid | F4: Histidine Metabolism | G4: 1-methyl-5-imidazoleacetate | I4: 1-methyl-5-imidazoleacetate | L4: 1-methyl-5-imidazoleacetate levels | M4: GCST90199901 | N4: Amino Acid | P4: Histidine Metabolism | R4: Amino Acid
A5: metab_compid_64596 | B5: metabolon | C5: 1-methyl-5-imidazolelactate | D5: =_xlfn.XLOOKUP(E5,pathways!$A$2:$A$31,pathways!$B$2:$B$31) -> Amino acid metabolism | E5: Amino Acid | F5: Histidine Metabolism | I5: 1-methyl-5-imidazolelactate | N5: Amino Acid | P5: Histidine Metabolism
A6: metab_compid_30460 | B6: metabolon | C6: 1-methylhistidine | D6: =_xlfn.XLOOKUP(E6,pathways!$A$2:$A$31,pathways!$B$2:$B$31) -> Amino acid metabolism | E6: Amino Acid | F6: Histidine Metabolism | G6: 1-methylhistidine | I6: 1-methylhistidine | J6: 1-methylhistidine | L6: 1-methylhistidine levels | M6: GCST90199691 | N6: Amino Acid | O6: Amino Acid | P6: Histidine Metabolism | Q6: Histidine Metabolism | R6: Amino Acid | S6: Phosphatidylserine (PS)
A7: metab_compid_61868 | B7: metabolon | C7: 1-ribosyl-imidazoleacetate | D7: =_xlfn.XLOOKUP(E7,pathways!$A$2:$A$31,pathways!$B$2:$B$31) -> Amino acid metabolism | E7: Amino Acid | F7: Histidine Metabolism | G7: 1-ribosyl-imidazoleacetate | I7: 1-ribosyl-imidazoleacetate* | J7: 1-ribosyl-imidazoleacetate* | L7: 1-ribosyl-imidazoleacetate levels | M7: GCST90199815 | N7: Amino Acid | O7: Amino Acid | P7: Histidine Metabolism | Q7: Histidine Metabolism | R7: Amino Acid
A8: metab_compid_6146 | B8: metabolon | C8: 2-aminoadipate | D8: =_xlfn.XLOOKUP(E8,pathways!$A$2:$A$31,pathways!$B$2:$B$31) -> Amino acid metabolism | E8: Amino Acid | F8: Lysine Metabolism | I8: 2-aminoadipate | J8: 2-aminoadipate | N8: Amino Acid | O8: Amino Acid | P8: Lysine Metabolism | Q8: Lysine Metabolism
A9: metab_compid_42374 | B9: metabolon | C9: 2-aminobutyrate | D9: =_xlfn.XLOOKUP(E9,pathways!$A$2:$A$31,pathways!$B$2:$B$31) -> Amino acid metabolism | E9: Amino Acid | F9: Glutathione Metabolism | G9: 2-aminobutyrate | I9: 2-aminobutyrate | J9: 2-aminobutyrate | L9: 2-aminobutyrate levels | M9: GCST90200305 | N9: Amino Acid | O9: Amino Acid | P9: Glutathione Metabolism | Q9: Glutathione Metabolism | R9: Amino Acid
A10: metab_compid_36746 | B10: metabolon | C10: 2-hydroxy-3-methylvalerate | D10: =_xlfn.XLOOKUP(E10,pathways!$A$2:$A$31,pathways!$B$2:$B$31) -> Amino acid metabolism | E10: Amino Acid | F10: Leucine, Isoleucine and Valine Metabolism | I10: 2-hydroxy-3-methylvalerate | J10: 2-hydroxy-3-methylvalerate | L10: 2-hydroxy-3-methylvalerate levels | M10: GCST90199786 | N10: Amino Acid | O10: Amino Acid | P10: Leucine, Isoleucine and Valine Metabolism | Q10: Leucine, Isoleucine and Valine Metabolism | R10: Amino Acid
A11: metab_compid_63739 | B11: metabolon | C11: 2-hydroxy-4-(methylthio)butanoic acid | D11: =_xlfn.XLOOKUP(E11,pathways!$A$2:$A$31,pathways!$B$2:$B$31) -> Amino acid metabolism | E11: Amino Acid | F11: Methionine, Cysteine, SAM and Taurine Metabolism | I11: 2-hydroxy-4-(methylthio)butanoic acid | L11: 2-hydroxy-4-(methylthio)butanoic acid levels | M11: GCST90200258 | N11: Amino Acid | P11: Methionine, Cysteine, SAM and Taurine Metabolism | R11: Amino Acid | S11: Fatty Acid, Monohydroxy
A12: metab_compid_52281 | B12: metabolon | C12: 2-hydroxybutyrate/2-hydroxyisobutyrate | D12: =_xlfn.XLOOKUP(E12,pathways!$A$2:$A$31,pathways!$B$2:$B$31) -> Amino acid metabolism | E12: Amino Acid | F12: Glutathione Metabolism | I12: 2-hydroxybutyrate/2-hydroxyisobutyrate | J12: 2-hydroxybutyrate/2-hydroxyisobutyrate | L12: 2-hydroxybutyrate/2-hydroxyisobutyrate levels | M12: GCST90200032 | N12: Amino Acid | O12: Amino Acid | P12: Glutathione Metabolism | Q12: Glutathione Metabolism | R12: Amino Acid | S12: Fatty Acid, Monohydroxy
A13: metab_compid_1432 | B13: metabolon | C13: 2-hydroxyphenylacetate | D13: =_xlfn.XLOOKUP(E13,pathways!$A$2:$A$31,pathways!$B$2:$B$31) -> Amino acid metabolism | E13: Amino Acid | F13: Phenylalanine Metabolism | G13: 2-hydroxyphenylacetate | I13: 2-hydroxyphenylacetate | J13: 2-hydroxyphenylacetate | L13: 2-hydroxyphenylacetate levels | M13: GCST90200369 | N13: Amino Acid | O13: Amino Acid | P13: Phenylalanine Metabolism | Q13: Tyrosine Metabolism | R13: Amino Acid
A14: metab_compid_63120 | B14: metabolon | C14: 2-ketocaprylate | D14: =_xlfn.XLOOKUP(E14,pathways!$A$2:$A$31,pathways!$B$2:$B$31) -> Amino acid metabolism | E14: Amino Acid | F14: Leucine, Isoleucine and Valine Metabolism | I14: 2-ketocaprylate | L14: 2-ketocaprylate levels | M14: GCST90200224 | N14: Amino Acid | P14: Leucine, Isoleucine and Valine Metabolism | R14: Amino Acid
A15: metab_compid_45095 | B15: metabolon | C15: 2-methylbutyrylcarnitine (C5) | D15: =_xlfn.XLOOKUP(E15,pathways!$A$2:$A$31,pathways!$B$2:$B$31) -> Amino acid metabolism | E15: Amino Acid | F15: Leucine, Isoleucine and Valine Metabolism | I15: 2-methylbutyrylcarnitine (C5) | J15: 2-methylbutyrylcarnitine (C5) | N15: Amino Acid | O15: Amino Acid | P15: Leucine, Isoleucine and Valine Metabolism | Q15: Leucine, Isoleucine and Valine Metabolism
A16: metab_compid_55072 | B16: metabolon | C16: 2-oxoarginine | D16: =_xlfn.XLOOKUP(E16,pathways!$A$2:$A$31,pathways!$B$2:$B$31) -> Amino acid metabolism | E16: Amino Acid | F16: Urea cycle; Arginine and Proline Metabolism | I16: 2-oxoarginine* | J16: 2-oxoarginine* | L16: 2-oxoarginine levels | M16: GCST90199903 | N16: Amino Acid | O16: Amino Acid | P16: Urea cycle; Arginine and Proline Metabolism | Q16: Urea cycle; Arginine and Proline Metabolism | R16: Amino Acid
A17: metab_compid_31675 | B17: metabolon | C17: 2-pyrrolidinone | D17: =_xlfn.XLOOKUP(E17,pathways!$A$2:$A$31,pathways!$B$2:$B$31) -> Amino acid metabolism | E17: Amino Acid | F17: Glutamate Metabolism | I17: 2-pyrrolidinone | J17: 2-pyrrolidinone | N17: Amino Acid | O17: Amino Acid | P17: Glutamate Metabolism | Q17: Glutamate Metabolism
A18: metab_compid_57547 | B18: metabolon | C18: 2,3-dihydroxy-2-methylbutyrate | D18: =_xlfn.XLOOKUP(E18,pathways!$A$2:$A$31,pathways!$B$2:$B$31) -> Amino acid metabolism | E18: Amino Acid | F18: Leucine, Isoleucine and Valine Metabolism | G18: 2,3-dihydroxy-2-methylbutyrate | I18: 2,3-dihydroxy-2-methylbutyrate | J18: 2,3-dihydroxy-2-methylbutyrate | L18: 2,3-dihydroxy-2-methylbutyrate levels | M18: GCST90200112 | N18: Amino Acid | O18: Amino Acid | P18: Leucine, Isoleucine and Valine Metabolism | Q18: Leucine, Isoleucine and Valine Metabolism | R18: Amino Acid | S18: Sterol
A19: metab_compid_62805 | B19: metabolon | C19: 2,3-dihydroxy-5-methylthio-4-pentenoate (dmtpa) | D19: =_xlfn.XLOOKUP(E19,pathways!$A$2:$A$31,pathways!$B$2:$B$31) -> Amino acid metabolism | E19: Amino Acid | F19: Methionine, Cysteine, SAM and Taurine Metabolism | G19: 2,3-dihydroxy-5-methylthio-4-pentenoate (DMTPA) | I19: 2,3-dihydroxy-5-methylthio-4-pentenoate (DMTPA)* | L19: 2,3-dihydroxy-5-methylthio-4-pentenoate (dmtpa) levels | M19: GCST90200233 | N19: Amino Acid | P19: Methionine, Cysteine, SAM and Taurine Metabolism | R19: Amino Acid
A20: metab_compid_32197 | B20: metabolon | C20: 3-(4-hydroxyphenyl)lactate | D20: =_xlfn.XLOOKUP(E20,pathways!$A$2:$A$31,pathways!$B$2:$B$31) -> Amino acid metabolism | E20: Amino Acid | F20: Tyrosine Metabolism | I20: 3-(4-hydroxyphenyl)lactate | J20: 3-(4-hydroxyphenyl)lactate | L20: 3-(4-hydroxyphenyl)lactate levels | M20: GCST90200371 | N20: Amino Acid | O20: Amino Acid | P20: Tyrosine Metabolism | Q20: Tyrosine Metabolism | R20: Amino Acid | S20: Xanthine Metabolism
A21: metab_compid_62853 | B21: metabolon | C21: 3-amino-2-piperidone | D21: =_xlfn.XLOOKUP(E21,pathways!$A$2:$A$31,pathways!$B$2:$B$31) -> Amino acid metabolism | E21: Amino Acid | F21: Urea cycle; Arginine and Proline Metabolism | G21: 3-amino-2-piperidone | I21: 3-amino-2-piperidone | L21: 3-amino-2-piperidone levels | M21: GCST90200188 | N21: Amino Acid | P21: Urea cycle; Arginine and Proline Metabolism | R21: Amino Acid
A22: metab_compid_32397 | B22: metabolon | C22: 3-hydroxy-2-ethylpropionate | D22: =_xlfn.XLOOKUP(E22,pathways!$A$2:$A$31,pathways!$B$2:$B$31) -> Amino acid metabolism | E22: Amino Acid | F22: Leucine, Isoleucine and Valine Metabolism | I22: 3-hydroxy-2-ethylpropionate | J22: 3-hydroxy-2-ethylpropionate | L22: 3-hydroxy-2-ethylpropionate levels | M22: GCST90199714 | N22: Amino Acid | O22: Amino Acid | P22: Leucine, Isoleucine and Valine Metabolism | Q22: Leucine, Isoleucine and Valine Metabolism | R22: Amino Acid
A23: metab_compid_1549 | B23: metabolon | C23: 3-hydroxyisobutyrate | D23: =_xlfn.XLOOKUP(E23,pathways!$A$2:$A$31,pathways!$B$2:$B$31) -> Amino acid metabolism | E23: Amino Acid | F23: Leucine, Isoleucine and Valine Metabolism | I23: 3-hydroxyisobutyrate | J23: 3-hydroxyisobutyrate | L23: 3-hydroxyisobutyrate levels | M23: GCST90200308 | N23: Amino Acid | O23: Amino Acid | P23: Leucine, Isoleucine and Valine Metabolism | Q23: Leucine, Isoleucine and Valine Metabolism | R23: Amino Acid
A24: metab_compid_27672 | B24: metabolon | C24: 3-indoxyl sulfate | D24: =_xlfn.XLOOKUP(E24,pathways!$A$2:$A$31,pathways!$B$2:$B$31) -> Amino acid metabolism | E24: Amino Acid | F24: Tryptophan Metabolism | I24: 3-indoxyl sulfate | J24: 3-indoxyl sulfate | L24: 3-indoxyl sulfate levels | M24: GCST90199656 | N24: Amino Acid | O24: Amino Acid | P24: Tryptophan Metabolism | Q24: Tryptophan Metabolism | R24: Amino Acid
A25: metab_compid_44618 | B25: metabolon | C25: 3-methoxytyramine sulfate | D25: =_xlfn.XLOOKUP(E25,pathways!$A$2:$A$31,pathways!$B$2:$B$31) -> Amino acid metabolism | E25: Amino Acid | F25: Tyrosine Metabolism | J25: 3-methoxytyramine sulfate | L25: 3-methoxytyramine sulfate levels | M25: GCST90199953 | O25: Amino Acid | Q25: Tyrosine Metabolism | R25: Amino Acid | S25: Fatty Acid, Monohydroxy
A26: metab_compid_12017 | B26: metabolon | C26: 3-methoxytyrosine | D26: =_xlfn.XLOOKUP(E26,pathways!$A$2:$A$31,pathways!$B$2:$B$31) -> Amino acid metabolism | E26: Amino Acid | F26: Tyrosine Metabolism | G26: 3-methoxytyrosine | I26: 3-methoxytyrosine | J26: 3-methoxytyrosine | L26: 3-methoxytyrosine levels | M26: GCST90200328 | N26: Amino Acid | O26: Amino Acid | P26: Tyrosine Metabolism | Q26: Tyrosine Metabolism | R26: Amino Acid
A27: metab_compid_44526 | B27: metabolon | C27: 3-methyl-2-oxobutyrate | D27: =_xlfn.XLOOKUP(E27,pathways!$A$2:$A$31,pathways!$B$2:$B$31) -> Amino acid metabolism | E27: Amino Acid | F27: Leucine, Isoleucine and Valine Metabolism | I27: 3-methyl-2-oxobutyrate | J27: 3-methyl-2-oxobutyrate | L27: 3-methyl-2-oxobutyrate levels | M27: GCST90199677 | N27: Amino Acid | O27: Amino Acid | P27: Leucine, Isoleucine and Valine Metabolism | Q27: Leucine, Isoleucine and Valine Metabolism | R27: Amino Acid
A28: metab_compid_15676 | B28: metabolon | C28: 3-methyl-2-oxovalerate | D28: =_xlfn.XLOOKUP(E28,pathways!$A$2:$A$31,pathways!$B$2:$B$31) -> Amino acid metabolism | E28: Amino Acid | F28: Leucine, Isoleucine and Valine Metabolism | I28: 3-methyl-2-oxovalerate | J28: 3-methyl-2-oxovalerate | L28: 3-methyl-2-oxovalerate levels | M28: GCST90199631 | N28: Amino Acid | O28: Amino Acid | P28: Leucine, Isoleucine and Valine Metabolism | Q28: Leucine, Isoleucine and Valine Metabolism | R28: Amino Acid
A29: metab_compid_57747 | B29: metabolon | C29: 3-methylglutaconate | D29: =_xlfn.XLOOKUP(E29,pathways!$A$2:$A$31,pathways!$B$2:$B$31) -> Amino acid metabolism | E29: Amino Acid | F29: Leucine, Isoleucine and Valine Metabolism | I29: 3-methylglutaconate | J29: 3-methylglutaconate | L29: 3-methylglutaconate levels | M29: GCST90199886 | N29: Amino Acid | O29: Amino Acid | P29: Leucine, Isoleucine and Valine Metabolism | Q29: Leucine, Isoleucine and Valine Metabolism | R29: Amino Acid
A30: metab_compid_46548 | B30: metabolon | C30: 3-methylglutarylcarnitine (2) | D30: =_xlfn.XLOOKUP(E30,pathways!$A$2:$A$31,pathways!$B$2:$B$31) -> Amino acid metabolism | E30: Amino Acid | F30: Leucine, Isoleucine and Valine Metabolism | I30: 3-methylglutarylcarnitine (2) | L30: 3-methylglutarylcarnitine (2) levels | M30: GCST90199971 | N30: Amino Acid | P30: Leucine, Isoleucine and Valine Metabolism | R30: Amino Acid
A31: metab_compid_15677 | B31: metabolon | C31: 3-methylhistidine | D31: =_xlfn.XLOOKUP(E31,pathways!$A$2:$A$31,pathways!$B$2:$B$31) -> Amino acid metabolism | E31: Amino Acid | F31: Histidine Metabolism | I31: 3-methylhistidine | J31: 3-methylhistidine | L31: 3-methylhistidine levels | M31: GCST90199628 | N31: Amino Acid | O31: Amino Acid | P31: Histidine Metabolism | Q31: Histidine Metabolism | R31: Amino Acid
A32: metab_compid_47089 | B32: metabolon | C32: 3-sulfo-L-alanine | D32: =_xlfn.XLOOKUP(E32,pathways!$A$2:$A$31,pathways!$B$2:$B$31) -> Amino acid metabolism | E32: Amino Acid | F32: Methionine, Cysteine, SAM and Taurine Metabolism | I32: 3-sulfo-alanine | J32: 3-sulfo-L-alanine | N32: Amino Acid | O32: Amino Acid | P32: Methionine, Cysteine, SAM and Taurine Metabolism | Q32: Methionine, Cysteine, SAM and Taurine Metabolism | S32: Chemical
A33: metab_compid_1558 | B33: metabolon | C33: 4-acetamidobutanoate | D33: =_xlfn.XLOOKUP(E33,pathways!$A$2:$A$31,pathways!$B$2:$B$31) -> Amino acid metabolism | E33: Amino Acid | F33: Polyamine Metabolism | G33: 4-acetamidobutanoate | I33: 4-acetamidobutanoate | L33: 4-acetamidobutanoate levels | M33: GCST90200311 | N33: Amino Acid | P33: Polyamine Metabolism | R33: Amino Acid | S33: Glutamate Metabolism
A34: metab_compid_15681 | B34: metabolon | C34: 4-guanidinobutanoate | D34: =_xlfn.XLOOKUP(E34,pathways!$A$2:$A$31,pathways!$B$2:$B$31) -> Amino acid metabolism | E34: Amino Acid | F34: Guanidino and Acetamido Metabolism | G34: 4-guanidinobutanoate | I34: 4-guanidinobutanoate | J34: 4-guanidinobutanoate | L34: 4-guanidinobutanoate levels | M34: GCST90199640 | N34: Amino Acid | O34: Amino Acid | P34: Guanidino and Acetamido Metabolism | Q34: Guanidino and Acetamido Metabolism | R34: Amino Acid
A35: metab_compid_40499 | B35: metabolon | C35: 4-hydroxyglutamate | D35: =_xlfn.XLOOKUP(E35,pathways!$A$2:$A$31,pathways!$B$2:$B$31) -> Amino acid metabolism | E35: Amino Acid | F35: Glutamate Metabolism | I35: 4-hydroxyglutamate | L35: 4-hydroxyglutamate levels | M35: GCST90199890 | N35: Amino Acid | P35: Glutamate Metabolism | R35: Amino Acid
A36: metab_compid_541 | B36: metabolon | C36: 4-hydroxyphenylacetate | D36: =_xlfn.XLOOKUP(E36,pathways!$A$2:$A$31,pathways!$B$2:$B$31) -> Amino acid metabolism | E36: Amino Acid | F36: Phenylalanine Metabolism | G36: 4-hydroxyphenylacetate | I36: 4-hydroxyphenylacetate | L36: 4-hydroxyphenylacetate levels | M36: GCST90200338 | N36: Amino Acid | P36: Phenylalanine Metabolism | R36: Amino Acid
A37: metab_compid_1669 | B37: metabolon | C37: 4-hydroxyphenylpyruvate | D37: =_xlfn.XLOOKUP(E37,pathways!$A$2:$A$31,pathways!$B$2:$B$31) -> Amino acid metabolism | E37: Amino Acid | F37: Tyrosine Metabolism | G37: 4-hydroxyphenylpyruvate | I37: 4-hydroxyphenylpyruvate | J37: 4-hydroxyphenylpyruvate | L37: 4-hydroxyphenylpyruvate levels | M37: GCST90200300 | N37: Amino Acid | O37: Amino Acid | P37: Tyrosine Metabolism | Q37: Tyrosine Metabolism | R37: Amino Acid
A38: metab_compid_48457 | B38: metabolon | C38: 4-methoxyphenol sulfate | D38: =_xlfn.XLOOKUP(E38,pathways!$A$2:$A$31,pathways!$B$2:$B$31) -> Amino acid metabolism | E38: Amino Acid | F38: Tyrosine Metabolism | I38: 4-methoxyphenol sulfate | J38: 4-methoxyphenol sulfate | L38: 4-methoxyphenol sulfate levels | M38: GCST90199999 | N38: Amino Acid | O38: Amino Acid | P38: Tyrosine Metabolism | Q38: Tyrosine Metabolism | R38: Amino Acid | S38: Tyrosine Metabolism
A39: metab_compid_22116 | B39: metabolon | C39: 4-methyl-2-oxopentanoate | D39: =_xlfn.XLOOKUP(E39,pathways!$A$2:$A$31,pathways!$B$2:$B$31) -> Amino acid metabolism | E39: Amino Acid | F39: Leucine, Isoleucine and Valine Metabolism | I39: 4-methyl-2-oxopentanoate | J39: 4-methyl-2-oxopentanoate | L39: 4-methyl-2-oxopentanoate levels | M39: GCST90199655 | N39: Amino Acid | O39: Amino Acid | P39: Leucine, Isoleucine and Valine Metabolism | Q39: Leucine, Isoleucine and Valine Metabolism | R39: Amino Acid | S39: Glycogen Metabolism
A40: metab_compid_43582 | B40: metabolon | C40: 5-(galactosylhydroxy)-L-lysine | D40: =_xlfn.XLOOKUP(E40,pathways!$A$2:$A$31,pathways!$B$2:$B$31) -> Amino acid metabolism | E40: Amino Acid | F40: Lysine Metabolism | G40: 5-(galactosylhydroxy)-L-lysine | I40: 5-(galactosylhydroxy)-lysine | J40: 5-(galactosylhydroxy)-L-lysine | L40: 5-(galactosylhydroxy)-L-lysine levels | M40: GCST90199881 | N40: Amino Acid | O40: Amino Acid | P40: Lysine Metabolism | Q40: Lysine Metabolism | R40: Amino Acid | S40: Benzoate Metabolism
...

Sheet gwas_metab_name_map
A1: ukbb_std_name | B1: ukbb_raw_name | C1: outcome | D1: bbs_feature_id | E1: bbs_chemical_name | F1: bbs_pathway | G1: bbs_sub_pathway | H1: unsure | I1: comment
A2: 3_hydroxybutyrate | B2: 3-Hydroxybutyrate | C2: 3-Hydroxybutyrate levels | D2: metab_bohbutyrate | E2: 3-Hydroxybutyrate | F2: Ketone bodies | G2: Ketone bodies
A3: acetate | B3: Acetate | C3: Acetate levels | D3: metab_acetate | E3: Acetate | F3: Ketone bodies | G3: Ketone bodies
A4: acetoacetate | B4: Acetoacetate | C4: Acetoacetate levels | D4: metab_acetoacetate | E4: Acetoacetate | F4: Ketone bodies | G4: Ketone bodies
A5: acetone | B5: Acetone | C5: Acetone levels | D5: metab_acetone | E5: Acetone | F5: Ketone bodies | G5: Ketone bodies
A6: alanine | B6: Alanine | C6: Alanine levels | D6: metab_ala | E6: Alanine | F6: Amino acids | G6: Amino acids
A7: albumin | B7: Albumin | C7: Albumin levels | D7: metab_albumin | E7: Albumin | F7: Fluid balance | G7: Fluid balance
A8: apolipoprotein_a1 | B8: Apolipoprotein A1 | C8: Apolipoprotein A-I levels | D8: metab_apoa1 | E8: Apolipoprotein A-I | F8: Apolipoproteins | G8: Apolipoproteins
A9: apolipoprotein_b | B9: Apolipoprotein B | C9: Apolipoprotein B levels | D9: metab_apob | E9: Apolipoprotein B | F9: Apolipoproteins | G9: Apolipoproteins
A10: apolipoprotein_b_to_apolipoprotein_a1_ratio | B10: Apolipoprotein B to Apolipoprotein A1 ratio | C10: Ratio of apolipoprotein B to apolipoprotein A1 levels | D10: metab_apobapoa1 | E10: Apolipoprotein B/A-I | F10: Apolipoproteins | G10: Apolipoproteins
A11: average_diameter_for_hdl_particles | B11: Average Diameter for HDL Particles | C11: Mean diameter of HDL particles | D11: metab_hdlsize | E11: Average diameter for HDL particles | F11: Lipoprotein particle sizes | G11: Lipoprotein particle sizes
A12: average_diameter_for_ldl_particles | B12: Average Diameter for LDL Particles | C12: Mean diameter of LDL particles | D12: metab_ldlsize | E12: Average diameter for LDL particles | F12: Lipoprotein particle sizes | G12: Lipoprotein particle sizes
A13: average_diameter_for_vldl_particles | B13: Average Diameter for VLDL Particles | C13: Mean diameter of VLDL particles | D13: metab_vldlsize | E13: Average diameter for VLDL particles | F13: Lipoprotein particle sizes | G13: Lipoprotein particle sizes
... A42: cholesteryl_esters_in_chylomicrons_and_extremely_large_vldl | B42: Cholesteryl Esters in Chylomicrons and Extremely Large VLDL | C42: Cholesteryl ester levels in chylomicrons and extremely large VLDL | D42: metab_xxlvldlce | E42: Cholesterol esters | F42: Lipoprotein subclasses | G42: Extremely large VLDL
A43: cholesteryl_esters_in_hdl | B43: Cholesteryl Esters in HDL | D43: metab_hdlce | E43: Cholesteryl esters in HDL | F43: Cholesteryl esters | G43: Cholesteryl esters
A44: cholesteryl_esters_in_idl | B44: Cholesteryl Esters in IDL | C44: Cholesterol esters in IDL | D44: metab_idlce | E44: Cholesterol esters | F44: Lipoprotein subclasses | G44: IDL
A45: cholesteryl_esters_in_large_hdl | B45: Cholesteryl Esters in Large HDL | C45: Cholesterol esters in large HDL | D45: metab_lhdlce | E45: Cholesterol esters | F45: Lipoprotein subclasses | G45: Large HDL
A46: cholesteryl_esters_in_large_ldl | B46: Cholesteryl Esters in Large LDL | C46: Cholesterol esters in large LDL | D46: metab_lldlce | E46: Cholesterol esters | F46: Lipoprotein subclasses | G46: Large LDL
A47: cholesteryl_esters_in_large_vldl | B47: Cholesteryl Esters in Large VLDL | C47: Cholesterol esters in large VLDL | D47: metab_lvldlce | E47: Cholesterol esters | F47: Lipoprotein subclasses | G47: Large VLDL
A48: cholesteryl_esters_in_ldl | B48: Cholesteryl Esters in LDL | D48: metab_ldlce | E48: Cholesteryl esters in LDL | F48: Cholesteryl esters | G48: Cholesteryl esters
A49: cholesteryl_esters_in_medium_hdl | B49: Cholesteryl Esters in Medium HDL | C49: Cholesterol esters in medium HDL | D49: metab_mhdlce | E49: Cholesterol esters | F49: Lipoprotein subclasses | G49: Medium HDL
A50: cholesteryl_esters_in_medium_ldl | B50: Cholesteryl Esters in Medium LDL | C50: Cholesterol esters in medium LDL | D50: metab_mldlce | E50: Cholesterol esters | F50: Lipoprotein subclasses | G50: Medium LDL
A51: cholesteryl_esters_in_medium_vldl | B51: Cholesteryl Esters in Medium VLDL | C51: Cholesterol esters in medium VLDL | D51: metab_mvldlce | E51: Cholesterol esters | F51: Lipoprotein subclasses | G51: Medium VLDL
A52: cholesteryl_esters_in_small_hdl | B52: Cholesteryl Esters in Small HDL | C52: Cholesterol esters in small HDL | D52: metab_shdlce | E52: Cholesterol esters | F52: Lipoprotein subclasses | G52: Small HDL
A53: cholesteryl_esters_in_small_ldl | B53: Cholesteryl Esters in Small LDL | C53: Cholesterol esters in small LDL | D53: metab_sldlce | E53: Cholesterol esters | F53: Lipoprotein subclasses | G53: Small LDL
A54: cholesteryl_esters_in_small_vldl | B54: Cholesteryl Esters in Small VLDL | C54: Cholesterol esters in small VLDL | D54: metab_svldlce | E54: Cholesterol esters | F54: Lipoprotein subclasses | G54: Small VLDL
A55: cholesteryl_esters_in_very_large_hdl | B55: Cholesteryl Esters in Very Large HDL | C55: Cholesterol esters in very large HDL | D55: metab_xlhdlce | E55: Cholesterol esters | F55: Lipoprotein subclasses | G55: Very large HDL
A56: cholesteryl_esters_in_very_large_vldl | B56: Cholesteryl Esters in Very Large VLDL | C56: Cholesterol esters in very large VLDL | D56: metab_xlvldlce | E56: Cholesterol esters | F56: Lipoprotein subclasses | G56: Very large VLDL
A57: cholesteryl_esters_in_very_small_vldl | B57: Cholesteryl Esters in Very Small VLDL | C57: Cholesterol esters in very small VLDL | D57: metab_xsvldlce | E57: Cholesterol esters | F57: Lipoprotein subclasses | G57: Very Small VLDL
A58: cholesteryl_esters_in_vldl | B58: Cholesteryl Esters in VLDL | D58: metab_vldlce | E58: Cholesteryl esters in VLDL | F58: Cholesteryl esters | G58: Cholesteryl esters
A59: cholesteryl_esters_to_total_lipids_in_chylomicrons_and_extremely_large_vldl_percentage | B59: Cholesteryl Esters to Total Lipids in Chylomicrons and Extremely Large VLDL percentage | C59: Cholesteryl esters to total lipids ratio in chylomicrons and extremely large VLDL | D59: metab_xxlvldlcepct | E59: Ratio | F59: Lipoprotein subclasses ratios | G59: Extremely large VLDL ratios
A60: cholesteryl_esters_to_total_lipids_in_idl_percentage | B60: Cholesteryl Esters to Total Lipids in IDL percentage | C60: Cholesteryl esters to total lipids ratio in IDL | D60: metab_idlcepct | E60: Ratio | F60: Lipoprotein subclasses ratios | G60: IDL ratios
A61: cholesteryl_esters_to_total_lipids_in_large_hdl_percentage | B61: Cholesteryl Esters to Total Lipids in Large HDL percentage | C61: Cholesteryl esters to total lipids ratio in large HDL | D61: metab_lhdlcepct | E61: Ratio | F61: Lipoprotein subclasses ratios | G61: Large HDL ratios
A62: cholesteryl_esters_to_total_lipids_in_large_ldl_percentage | B62: Cholesteryl Esters to Total Lipids in Large LDL percentage | C62: Cholesteryl esters to total lipids ratio in large LDL | D62: metab_lldlcepct | E62: Ratio | F62: Lipoprotein subclasses ratios | G62: Large LDL ratios
A63: cholesteryl_esters_to_total_lipids_in_large_vldl_percentage | B63: Cholesteryl Esters to Total Lipids in Large VLDL percentage | C63: Cholesteryl esters to total lipids ratio in large VLDL | D63: metab_lvldlcepct | E63: Ratio | F63: Lipoprotein subclasses ratios | G63: Large VLDL ratios
A64: cholesteryl_esters_to_total_lipids_in_medium_hdl_percentage | B64: Cholesteryl Esters to Total Lipids in Medium HDL percentage | C64: Cholesteryl esters to total lipids ratio in medium HDL | D64: metab_mhdlcepct | E64: Ratio | F64: Lipoprotein subclasses ratios | G64: Medium HDL ratios
A65: cholesteryl_esters_to_total_lipids_in_medium_ldl_percentage | B65: Cholesteryl Esters to Total Lipids in Medium LDL percentage | C65: Cholesteryl esters to total lipids ratio in medium LDL | D65: metab_mldlcepct | E65: Ratio | F65: Lipoprotein subclasses ratios | G65: Medium LDL ratios
A66: cholesteryl_esters_to_total_lipids_in_medium_vldl_percentage | B66: Cholesteryl Esters to Total Lipids in Medium VLDL percentage | C66: Cholesteryl esters to total lipids ratio in medium VLDL | D66: metab_mvldlcepct | E66: Ratio | F66: Lipoprotein subclasses ratios | G66: Medium VLDL ratios
A67: cholesteryl_esters_to_total_lipids_in_small_hdl_percentage | B67: Cholesteryl Esters to Total Lipids in Small HDL percentage | C67: Cholesteryl esters to total lipids ratio in small HDL | D67: metab_shdlcepct | E67: Ratio | F67: Lipoprotein subclasses ratios | G67: Small HDL ratios
A68: cholesteryl_esters_to_total_lipids_in_small_ldl_percentage | B68: Cholesteryl Esters to Total Lipids in Small LDL percentage | C68: Cholesteryl esters to total lipids ratio in small LDL | D68: metab_sldlcepct | E68: Ratio | F68: Lipoprotein subclasses ratios | G68: Small LDL ratios
...

Sheet bbs_metabolon
A1: id | B1: CHEM_ID | C1: LIB_ID | D1: COMP_ID | E1: CHRO_LIB_ENTRY_ID | F1: SUPER_PATHWAY | G1: SUB_PATHWAY | H1: PATHWAY_SORTORDER | I1: TYPE | J1: INCHIKEY | K1: SMILES | L1: CHEMICAL_NAME | M1: PLOT_NAME | N1: CAS | O1: CHEMSPIDER | P1: HMDB | Q1: KEGG | R1: PUBCHEM | S1: PLATFORM
A2: =_xlfn.CONCAT("metab_compid_", $D2) -> metab_compid_38768 | B2: 100002945 | C2: 209 | D2: 38768 | E2: 143701 | F2: Lipid | G2: Fatty Acid, Branched | H2: 1660 | I2: NAMED | J2: IIUXHTGBZYEGHI-UHFFFAOYSA-N | K2: CC(CCCCCCCCCCCCCC(O)=O)C | L2: (14 or 15)-methylpalmitate (a17:0 or i17:0) | M2: (14 or 15)-methylpalmitate (a17:0 or i17:0) | P2: HMDB0061859 | Q2: C16995 | R2: 8181,17903417 | S2: Neg
A3: =_xlfn.CONCAT("metab_compid_", $D3) -> metab_compid_38296 | B3: 100002356 | C3: 209 | D3: 38296 | E3: 141846 | F3: Lipid | G3: Fatty Acid, Branched | H3: 1666 | I3: NAMED | J3: YETXGSGCWODRAA-UHFFFAOYSA-N | K3: OC(CCCCCCCCCCCCCCCC(C)C)=O | L3: (16 or 17)-methylstearate (a19:0 or i19:0) | M3: (16 or 17)-methylstearate (a19:0 or i19:0) | N3: 2724-59-6 | O3: 2340933 | P3: HMDB0037397 | R3: 3083779 | S3: Neg
A4: =_xlfn.CONCAT("metab_compid_", $D4) -> metab_compid_63436 | B4: 100021502 | C4: 209 | D4: 63436 | E4: 222605 | F4: Lipid | G4: Medium Chain Fatty Acid | H4: 1516 | I4: NAMED | J4: WXBXVVIUZANZAU-CMDGGOBGSA-N | K4: CCCCCCC/C=C/C(O)=O | L4: (2 or 3)-decenoate (10:1n7 or n8) | M4: (2 or 3)-decenoate (10:1n7 or n8) | S4: Neg
A5: =_xlfn.CONCAT("metab_compid_", $D5) -> metab_compid_62533 | B5: 100020519 | C5: 209 | D5: 62533 | E5: 219867 | F5: Xenobiotics | G5: Food Component/Plant | H5: 5225 | I5: NAMED | J5: CLCCTVXAPVYLKM-UHFFFAOYSA-N | K5: CC1=CC=C(C)C(OS(=O)(O)=O)=C1 | L5: (2,4 or 2,5)-dimethylphenol sulfate | M5: (2,4 or 2,5)-dimethylphenol sulfate | S5: Neg
A6: =_xlfn.CONCAT("metab_compid_", $D6) -> metab_compid_57814 | B6: 100016038 | C6: 400 | D6: 57814 | E6: 213597 | F6: Amino Acid | G6: Polyamine Metabolism | H6: 558 | I6: NAMED | J6: MQTAVJHICJWXBR-UHFFFAOYSA-N | K6: CC(NCCCNCCCCN)=O | L6: (N(1) + N(8))-acetylspermidine | M6: (N(1) + N(8))-acetylspermidine | P6: HMDB0002189,HMDB0001276 | Q6: C01029,C00612 | R6: 496,123689 | S6: Pos Early
A7: =_xlfn.CONCAT("metab_compid_", $D7) -> metab_compid_43264 | B7: 100003926 | C7: 400 | D7: 43264 | E7: 156990 | F7: Lipid | G7: Fatty Acid Metabolism (Acyl Carnitine, Hydroxy) | H7: 1937 | I7: NAMED | J7: UEFRDQSMQXDWTO-UHFFFAOYSA-N | K7: CC(CC(OC(C[N+](C)(C)C)CC([O-])=O)=O)O | L7: (R)-3-hydroxybutyrylcarnitine | M7: (R)-3-hydroxybutyrylcarnitine | P7: HMDB0013127 | R7: 53481617 | S7: Pos Early
A8: =_xlfn.CONCAT("metab_compid_", $D8) -> metab_compid_52984 | B8: 100009271 | C8: 400 | D8: 52984 | E8: 166220 | F8: Lipid | G8: Fatty Acid Metabolism (Acyl Carnitine, Hydroxy) | H8: 1938 | I8: NAMED | J8: UEFRDQSMQXDWTO-UHFFFAOYSA-N | K8: CC(O)CC(OC(C[N+](C)(C)C)CC([O-])=O)=O | L8: (S)-3-hydroxybutyrylcarnitine | M8: (S)-3-hydroxybutyrylcarnitine | P8: HMDB0013127 | R8: 71464477 | S8: Pos Early
A9: =_xlfn.CONCAT("metab_compid_", $D9) -> metab_compid_44621 | B9: 100005372 | C9: 402 | D9: 44621 | E9: 163990 | F9: Lipid | G9: Lysoplasmalogen | H9: 2855 | I9: NAMED | J9: URGVIWXYPWWBQO-ZCJATDNESA-N | K9: O=P(OCC[NH3+])([O-])OC[C@H](O)CO/C=C/CCCCCC/C=C/CCCCCCCC | L9: 1-(1-enyl-oleoyl)-GPE (P-18:1)* | M9: 1-(1-enyl-oleoyl)-GPE (P-18:1)* | S9: Pos Late
A10: =_xlfn.CONCAT("metab_compid_", $D10) -> metab_compid_52689 | B10: 100009014 | C10: 402 | D10: 52689 | E10: 165459 | F10: Lipid | G10: Plasmalogen | H10: 2831 | I10: NAMED | J10: IOYKZPNDXIIXLN-LOQSCQKMSA-N | K10: [H][C@](OC(CCC/C=C\C/C=C\C/C=C\C/C=C\CCCCC)=O)(COP(OCC[N+](C)(C)C)([O-])=O)CO/C=C\CCCCCCCCCCCCCC | L10: 1-(1-enyl-palmitoyl)-2-arachidonoyl-GPC (P-16:0/20:4)* | M10: 1-(1-enyl-palmitoyl)-2-arachidonoyl-GPC (P-16:0/20:4)* | O10: 24767495 | P10: HMDB0011220 | S10: Pos Late
A11: =_xlfn.CONCAT("metab_compid_", $D11) -> metab_compid_52673 | B11: 100009002 | C11: 402 | D11: 52673 | E11: 165435 | F11: Lipid | G11: Plasmalogen | H11: 2822 | I11: NAMED | J11: UUYSKERSKRMYME-MAIXUNBTSA-N | K11: [H][C@](OC(CCC/C=C\C/C=C\C/C=C\C/C=C\CCCCC)=O)(COP(OCCN)(O)=O)CO/C=C\CCCCCCCCCCCCCC | L11: 1-(1-enyl-palmitoyl)-2-arachidonoyl-GPE (P-16:0/20:4)* | M11: 1-(1-enyl-palmitoyl)-2-arachidonoyl-GPE (P-16:0/20:4)* | O11: 24769238 | P11: HMDB0011352 | R11: 52925126 | S11: Pos Late
A12: =_xlfn.CONCAT("metab_compid_", $D12) -> metab_compid_52682 | B12: 100009009 | C12: 402 | D12: 52682 | E12: 165449 | F12: Lipid | G12: Plasmalogen | H12: 2832 | I12: NAMED | J12: QLEHHUPUHJPURI-PWYDUFMYSA-N | K12: [H][C@](OC(CCCCCCC/C=C\C/C=C\CCCCC)=O)(COP(OCC[N+](C)(C)C)([O-])=O)CO/C=C\CCCCCCCCCCCCCC | L12: 1-(1-enyl-palmitoyl)-2-linoleoyl-GPC (P-16:0/18:2)* | M12: 1-(1-enyl-palmitoyl)-2-linoleoyl-GPC (P-16:0/18:2)* | O12: 24767486 | P12: HMDB0011211 | R12: 24779386 | S12: Pos Late
A13: =_xlfn.CONCAT("metab_compid_", $D13) -> metab_compid_52677 | B13: 100009069 | C13: 402 | D13: 52677 | E13: 165443 | F13: Lipid | G13: Plasmalogen | H13: 2819 | I13: NAMED | J13: LJVXDBWIBQQKFU-CCJYEBHUSA-N | K13: [H][C@](OC(CCCCCCC/C=C\C/C=C\CCCCC)=O)(COP(OCCN)(O)=O)CO/C=C\CCCCCCCCCCCCCC | L13: 1-(1-enyl-palmitoyl)-2-linoleoyl-GPE (P-16:0/18:2)* | M13: 1-(1-enyl-palmitoyl)-2-linoleoyl-GPE (P-16:0/18:2)* | O13: 24769229 | P13: HMDB0011343 | R13: 52925127 | S13: Pos Late
A14: =_xlfn.CONCAT("metab_compid_", $D14) -> metab_compid_52478 | B14: 100009007 | C14: 402 | D14: 52478 | E14: 165160 | F14: Lipid | G14: Plasmalogen | H14: 2824 | I14: NAMED | J14: CRBBMHQTIAELIS-KQBBALDBSA-N | K14: [H][C@](OC(CCCCCCC/C=C\CCCCCCCC)=O)(CO[P-](OCC[N+](C)(C)C)([O])=O)CO/C=C\CCCCCCCCCCCCCC | L14: 1-(1-enyl-palmitoyl)-2-oleoyl-GPC (P-16:0/18:1)* | M14: 1-(1-enyl-palmitoyl)-2-oleoyl-GPC (P-16:0/18:1)* | P14: HMDB0007996 | R14: 34779384 | S14: Pos Late
A15: =_xlfn.CONCAT("metab_compid_", $D15) -> metab_compid_52477 | B15: 100009005 | C15: 402 | D15: 52477 | E15: 165158 | F15: Lipid | G15: Plasmalogen | H15: 2818 | I15: NAMED | J15: ZVVYJAAMWXATNY-PRWZWGSOSA-N | K15: [H][C@](OC(CCCCCCC/C=C\CCCCCCCC)=O)(COP(OCCN)(O)=O)CO/C=C\CCCCCCCCCCCCCC | L15: 1-(1-enyl-palmitoyl)-2-oleoyl-GPE (P-16:0/18:1)* | M15: 1-(1-enyl-palmitoyl)-2-oleoyl-GPE (P-16:0/18:1)* | O15: 24769228 | P15: HMDB0011342 | R15: 52925128 | S15: Pos Late
A16: =_xlfn.CONCAT("metab_compid_", $D16) -> metab_compid_52713 | B16: 100009160 | C16: 402 | D16: 52713 | E16: 165492 | F16: Lipid | G16: Plasmalogen | H16: 2821 | I16: NAMED | J16: FZMYLOBGNYZPQO-QLSONYGBSA-N | K16: [H][C@](OC(CCCCCCC/C=C\CCCCCC)=O)(COP(OCC[N+](C)(C)C)([O-])=O)CO/C=C\CCCCCCCCCCCCCC | L16: 1-(1-enyl-palmitoyl)-2-palmitoleoyl-GPC (P-16:0/16:1)* | M16: 1-(1-enyl-palmitoyl)-2-palmitoleoyl-GPC (P-16:0/16:1)* | O16: 24767482 | P16: HMDB0011207 | R16: 52923882 | S16: Pos Late
A17: =_xlfn.CONCAT("metab_compid_", $D17) -> metab_compid_52716 | B17: 100009162 | C17: 402 | D17: 52716 | E17: 165495 | F17: Lipid | G17: Plasmalogen | H17: 2820 | I17: NAMED | J17: PEWXKAOBUSBJLD-MCBGMKGZSA-N | K17: [H][C@](OC(CCCCCCCCCCCCCCC)=O)(COP(OCC[N+](C)(C)C)([O-])=O)CO/C=C\CCCCCCCCCCCCCC | L17: 1-(1-enyl-palmitoyl)-2-palmitoyl-GPC (P-16:0/16:0)* | M17: 1-(1-enyl-palmitoyl)-2-palmitoyl-GPC (P-16:0/16:0)* | O17: 9322076 | P17: HMDB0011206 | R17: 11146967 | S17: Pos Late
A18: =_xlfn.CONCAT("metab_compid_", $D18) -> metab_compid_52474 | B18: 100002875 | C18: 402 | D18: 52474 | E18: 165152 | F18: Lipid | G18: Lysoplasmalogen | H18: 2852 | I18: NAMED | J18: HTZINLFNXLXRBC-CQLBIITFSA-N | K18: CCCCCCCCCCCCCC/C=C\OC[C@H](COP([O-])(OCC[N+](C)(C)C)=O)O | L18: 1-(1-enyl-palmitoyl)-GPC (P-16:0)* | M18: 1-(1-enyl-palmitoyl)-GPC (P-16:0)* | O18: 9093054 | P18: HMDB0010407 | R18: 10917802 | S18: Pos Late
A19: =_xlfn.CONCAT("metab_compid_", $D19) -> metab_compid_39270 | B19: 100003000 | C19: 402 | D19: 39270 | E19: 163991 | F19: Lipid | G19: Lysoplasmalogen | H19: 2853 | I19: NAMED | J19: QYTPGOPLNFESQC-RLHAVTDZSA-N | K19: O=P(OCC[NH3+])([O-])OC[C@H](O)CO/C=C/CCCCCCCCCCCCCC | L19: 1-(1-enyl-palmitoyl)-GPE (P-16:0)* | M19: 1-(1-enyl-palmitoyl)-GPE (P-16:0)* | O19: 10471193 | P19: HMDB0011152 | S19: Pos Late
A20: =_xlfn.CONCAT("metab_compid_", $D20) -> metab_compid_52475 | B20: 100008999 | C20: 402 | D20: 52475 | E20: 165154 | F20: Lipid | G20: Plasmalogen | H20: 2836 | I20: NAMED | J20: URPXXNCTXCOATD-FXMFQVEGSA-N | K20: [H][C@](OC(CCC/C=C\C/C=C\C/C=C\C/C=C\CCCCC)=O)(COP(OCCN)(O)=O)CO/C=C\CCCCCCCCCCCCCCCC | L20: 1-(1-enyl-stearoyl)-2-arachidonoyl-GPE (P-18:0/20:4)* | M20: 1-(1-enyl-stearoyl)-2-arachidonoyl-GPE (P-18:0/20:4)* | O20: 7826008 | P20: HMDB0005779 | R20: 9547058 | S20: Pos Late
A21: =_xlfn.CONCAT("metab_compid_", $D21) -> metab_compid_52748 | B21: 100009225 | C21: 402 | D21: 52748 | E21: 165539 | F21: Lipid | G21: Plasmalogen | H21: 2828 | I21: NAMED | J21: XVXISDREVDGQPX-PISDLAQISA-N | K21: [H][C@](OC(CCCCCCC/C=C\C/C=C\CCCCC)=O)(COP(OCCN)(O)=O)CO/C=C\CCCCCCCCCCCCCCCC | L21: 1-(1-enyl-stearoyl)-2-linoleoyl-GPE (P-18:0/18:2)* | M21: 1-(1-enyl-stearoyl)-2-linoleoyl-GPE (P-18:0/18:2)* | O21: 24769261 | P21: HMDB0011376 | S21: Pos Late
A22: =_xlfn.CONCAT("metab_compid_", $D22) -> metab_compid_52614 | B22: 100008919 | C22: 402 | D22: 52614 | E22: 165346 | F22: Lipid | G22: Plasmalogen | H22: 2827 | I22: NAMED | J22: XVYPOHCSLJZFED-QZEVRULJSA-N | K22: [H][C@@](COP([O-])(OCC[NH3+])=O)(OC(CCCCCCC/C=C\CCCCCCCC)=O)CO/C=C\CCCCCCCCCCCCCCCC | L22: 1-(1-enyl-stearoyl)-2-oleoyl-GPE (P-18:0/18:1) | M22: 1-(1-enyl-stearoyl)-2-oleoyl-GPE (P-18:0/18:1) | N22: 144371-68-6 | O22: 24769260 | P22: HMDB0011375 | R22: 42607457 | S22: Pos Late
A23: =_xlfn.CONCAT("metab_compid_", $D23) -> metab_compid_39271 | B23: 100003001 | C23: 402 | D23: 39271 | E23: 180976 | F23: Lipid | G23: Lysoplasmalogen | H23: 2857 | I23: NAMED | J23: KACDZDULGKPXHT-BIHRDVDLSA-N | K23: O=P(OCC[NH3+])([O-])OC[C@H](O)CO/C=C/CCCCCCCCCCCCCCCC | L23: 1-(1-enyl-stearoyl)-GPE (P-18:0)* | M23: 1-(1-enyl-stearoyl)-GPE (P-18:0)* | P23: HMDB0240598 | S23: Pos Late
A24: =_xlfn.CONCAT("metab_compid_", $D24) -> metab_compid_33228 | B24: 100001551 | C24: 402 | D24: 33228 | E24: 158552 | F24: Lipid | G24: Lysophospholipid | H24: 2653 | I24: NAMED | J24: LAXQYRRMGGEGOH-JXRLJXCWSA-N | K24: C[N+](C)(C)CCOP(OC[C@@](O)([H])COC(CCC\C=C/C\C=C/C/C=C\C/C=C\CCCCC)=O)([O-])=O | L24: 1-arachidonoyl-GPC (20:4n6)* | M24: 1-arachidonoyl-GPC (20:4n6)* | O24: 21403155 | P24: HMDB0010395 | Q24: C05208 | R24: 24779476 | S24: Pos Late
A25: =_xlfn.CONCAT("metab_compid_", $D25) -> metab_compid_35186 | B25: 100001571 | C25: 402 | D25: 35186 | E25: 158719 | F25: Lipid | G25: Lysophospholipid | H25: 2704 | I25: NAMED | J25: ROPRRXYVXLDXQO-XSQXPFHXSA-N | K25: NCCOP(OC[C@@](O)([H])COC(CCC\C=C/C\C=C/C/C=C\C/C=C\CCCCC)=O)(O)=O | L25: 1-arachidonoyl-GPE (20:4n6)* | M25: 1-arachidonoyl-GPE (20:4n6)* | O25: 21403171 | P25: HMDB0011517 | R25: 42607465 | S25: Pos Late
A26: =_xlfn.CONCAT("metab_compid_", $D26) -> metab_compid_34214 | B26: 100001654 | C26: 209 | D26: 34214 | E26: 142524 | F26: Lipid | G26: Lysophospholipid | H26: 2749 | I26: NAMED | J26: LXUGKKVCSTYZFK-OSKOXSHBSA-N | K26: [H]C(C(O)(C(O)([C@](O)1[H])[H])[H])([C@@](OP(O)(OC[C@@]([H])(COC(CCC/C=C\C/C=C\C/C=C\C/C=C\CCCCC)=O)O)=O)([C@]1(O)[H])[H])O | L26: 1-arachidonoyl-GPI (20:4)* | M26: 1-arachidonoyl-GPI (20:4)* | P26: HMDB0061690 | R26: 121596217 | S26: Neg
A27: =_xlfn.CONCAT("metab_compid_", $D27) -> metab_compid_34397 | B27: 100001433 | C27: 209 | D27: 34397 | E27: 126918 | F27: Lipid | G27: Monoacylglycerol | H27: 2881 | I27: NAMED | J27: DCPCOKIYJYGMDN-DOFZRALJSA-N | K27: O=C(CCC/C=C\C/C=C\C/C=C\C/C=C\CCCCC)OCC(O)CO | L27: 1-arachidonylglycerol (20:4) | M27: 1-arachidonylglycerol (20:4) | N27: 35474-99-8 | O27: 4445452 | P27: HMDB11578 | Q27: C13857 | R27: 16019980,5282281 | S27: Neg
A28: =_xlfn.CONCAT("metab_compid_", $D28) -> metab_compid_61505 | B28: 100015772 | C28: 402 | D28: 61505 | E28: 217727 | F28: Lipid | G28: Lysophospholipid | H28: 2675 | I28: NAMED | J28: WSDKRPCAPHRNNZ-MGBGTMOVSA-N | K28: C[N+](C)(CCOP([O-])(OC[C@@](O)([H])COC(CCCCCCCCCCCCCCCCCCCCCCCCC)=O)=O)C | L28: 1-cerotoyl-GPC (26:0)* | M28: 1-cerotoyl-GPC (26:0)* | O28: 35032836 | P28: HMDB29205 | S28: Pos Late
A29: =_xlfn.CONCAT("metab_compid_", $D29) -> metab_compid_48341 | B29: 100006121 | C29: 209 | D29: 48341 | E29: 153390 | F29: Lipid | G29: Monoacylglycerol | H29: 2880 | I29: NAMED | J29: LERKRWCYZNDWFH-QNEBEIHSSA-N | K29: OCC(O)COC(CCCCCC/C=C\C/C=C\C/C=C\CCCCC)=O | L29: 1-dihomo-linolenylglycerol (20:3) | M29: 1-dihomo-linolenylglycerol (20:3) | P29: HMDB0011577 | S29: Neg
A30: =_xlfn.CONCAT("metab_compid_", $D30) -> metab_compid_35153 | B30: 100001481 | C30: 209 | D30: 35153 | E30: 128209 | F30: Lipid | G30: Monoacylglycerol | H30: 2885 | I30: NAMED | J30: JWPHORDRFVRZPP-KUBAVDMBSA-N | K30: O=C(OCC(O)CO)CC/C=C\C/C=C\C/C=C\C/C=C\C/C=C\C/C=C\CC | L30: 1-docosahexaenoylglycerol (22:6) | M30: 1-docosahexaenoylglycerol (22:6) | O30: 10477810 | P30: HMDB0011587 | R30: 53480995 | S30: Neg
A31: =_xlfn.CONCAT("metab_compid_", $D31) -> metab_compid_62352 | B31: 100005376 | C31: 402 | D31: 62352 | E31: 240387 | F31: Lipid | G31: Lysophospholipid | H31: 2698 | I31: NAMED | J31: JEAGLCKGAKACCE-MDZDMXLPSA-N | K31: O=P(OCC(O)COC(CCCCCCCCC/C=C/CCCCCCCC)=O)(O)OCCN | L31: 1-eicosenoyl-GPE (20:1)* | M31: 1-eicosenoyl-GPE (20:1)* | P31: HMDB0011518 | R31: 52925139 | S31: Pos Late
A32: =_xlfn.CONCAT("metab_compid_", $D32) -> metab_compid_38140 | B32: 100002394 | C32: 209 | D32: 38140 | E32: 153530 | F32: Xenobiotics | G32: Drug - Other | H32: 6019 | I32: NAMED | J32: SJJCQDRGABAVBB-UHFFFAOYSA-N | K32: OC1=C(C(O)=O)C=CC2=C1C=CC=C2 | L32: 1-hydroxy-2-naphthalenecarboxylate | M32: 1-hydroxy-2-naphthalenecarboxylate | N32: 86-48-6 | O32: 6583 | Q32: C03203 | R32: 54675865 | S32: Neg
A33: =_xlfn.CONCAT("metab_compid_", $D33) -> metab_compid_49617 | B33: 100002873 | C33: 402 | D33: 49617 | E33: 161405 | F33: Lipid | G33: Lysophospholipid | H33: 2667 | I33: NAMED | J33: SKJMUADLQLZAGH-WJOKGBTCSA-N | K33: CCCCCCCCCCCCCCCCCCCCCCCC(OC[C@H](COP([O-])(OCC[N+](C)(C)C)=O)O)=O | L33: 1-lignoceroyl-GPC (24:0) | M33: 1-lignoceroyl-GPC (24:0) | N33: 325171-59-3 | O33: 24766539 | P33: HMDB0010405 | R33: 24779481 | S33: Pos Late
A34: =_xlfn.CONCAT("metab_compid_", $D34) -> metab_compid_45951 | B34: 100005350 | C34: 402 | D34: 45951 | E34: 159653 | F34: Lipid | G34: Lysophospholipid | H34: 2636 | I34: NAMED | J34: WKQNRCYKYCKESD-YHTMAJSVSA-N | K34: C[N+](CCOP(OCC(O)COC(CCCCCCC/C=C/C/C=C/C/C=C/CC)=O)([O-])=O)(C)C | L34: 1-linolenoyl-GPC (18:3)* | M34: 1-linolenoyl-GPC (18:3)* | P34: HMDB0010388 | Q34: C04100 | S34: Pos Late
A35: =_xlfn.CONCAT("metab_compid_", $D35) -> metab_compid_34393 | B35: 100001435 | C35: 209 | D35: 34393 | E35: 126910 | F35: Lipid | G35: Monoacylglycerol | H35: 2876 | I35: NAMED | J35: XQBHBEXBUZDCRY-QNEBEIHSSA-N | K35: O=C(OCC(O)CO)CCCC\C=C/C\C=C/C\C=C/CCCCC | L35: 1-linolenoylglycerol (18:3) | M35: 1-linolenoylglycerol (18:3) | N35: 124151-74-2 | O35: 21403134 | P35: HMDB0011569 | R35: 53480978 | S35: Neg
A36: =_xlfn.CONCAT("metab_compid_", $D36) -> metab_compid_52710 | B36: 100009131 | C36: 402 | D36: 52710 | E36: 165488 | F36: Lipid | G36: Phosphatidylcholine (PC) | H36: 2383 | I36: NAMED | J36: ZZSZQATYGVHNLZ-PUMLCSCDSA-N | K36: O=C(CCCCCCC/C=C\C/C=C\CCCCC)OC[C@]([H])(COP(OCC[N+](C)(C)C)([O-])=O)OC(CCC/C=C\C/C=C\C/C=C\C/C=C\CCCCC)=O | L36: 1-linoleoyl-2-arachidonoyl-GPC (18:2/20:4n6)* | M36: 1-linoleoyl-2-arachidonoyl-GPC (18:2/20:4n6)* | O36: 24766809 | P36: HMDB0008147 | Q36: C05208 | R36: 24778979 | S36: Pos Late
A37: =_xlfn.CONCAT("metab_compid_", $D37) -> metab_compid_53189 | B37: 100009222 | C37: 402 | D37: 53189 | E37: 166619 | F37: Lipid | G37: Phosphatidylethanolamine (PE) | H37: 2472 | I37: NAMED | J37: LFGBKOUQHCWBQI-BZGLIJSBSA-N | K37: O=C(CCCCCCC/C=C\C/C=C\CCCCC)OC[C@]([H])(COP(OCCN)(O)=O)OC(CCC/C=C\C/C=C\C/C=C\C/C=C\CCCCC)=O | L37: 1-linoleoyl-2-arachidonoyl-GPE (18:2/20:4)* | M37: 1-linoleoyl-2-arachidonoyl-GPE (18:2/20:4)* | O37: 24768565 | P37: HMDB0009102 | R37: 348279332 | S37: Pos Late
A38: =_xlfn.CONCAT("metab_compid_", $D38) -> metab_compid_53176 | B38: 100009343 | C38: 402 | D38: 53176 | E38: 166602 | F38: Lipid | G38: Phosphatidylcholine (PC) | H38: 2378 | I38: NAMED | J38: HZGAVPNEGHQJID-UNBCHYIMSA-N | K38: O=C(CCCCCCC/C=C\C/C=C\CCCCC)OC[C@]([H])(COP(OCC[N+](C)(C)C)([O-])=O)OC(CCCCCCC/C=C\C/C=C\C/C=C\CC)=O | L38: 1-linoleoyl-2-linolenoyl-GPC (18:2/18:3)* | M38: 1-linoleoyl-2-linolenoyl-GPC (18:2/18:3)* | O38: 24766802 | P38: HMDB0008141 | R38: 52922731 | S38: Pos Late
A39: =_xlfn.CONCAT("metab_compid_", $D39) -> metab_compid_34419 | B39: 100001395 | C39: 402 | D39: 34419 | E39: 158662 | F39: Lipid | G39: Lysophospholipid | H39: 2634 | I39: NAMED | J39: SPJFYYJXNPEZDW-UTJQPWESSA-N | K39: O=P(OCC(O)COC(CCCCCCC/C=C\C/C=C\CCCCC)=O)([O-])OCC[N+](C)(C)C | L39: 1-linoleoyl-GPC (18:2) | M39: 1-linoleoyl-GPC (18:2) | O39: 10160888 | P39: HMDB0010386 | Q39: C04100 | R39: 11988421 | S39: Pos Late
A40: =_xlfn.CONCAT("metab_compid_", $D40) -> metab_compid_36600 | B40: 100001570 | C40: 402 | D40: 36600 | E40: 158788 | F40: Lipid | G40: Lysophospholipid | H40: 2691 | I40: NAMED | J40: DBHKHNGBVGWQJE-HZJYTTRNSA-N | K40: O=P(OCC(O)COC(CCCCCCC/C=C\C/C=C\CCCCC)=O)(O)OCCN | L40: 1-linoleoyl-GPE (18:2)* | M40: 1-linoleoyl-GPE (18:2)* | O40: 21403170 | P40: HMDB0011507 | R40: 52925130 | S40: Pos Late
...

Sheet bbs_nightingale
A1: id | B1: feature_names | C1: raw.label | D1: class | E1: subclass | F1: label | G1: label.no.units
A2: =_xlfn.CONCAT("metab_", $B2) -> metab_acetate | B2: acetate | C2: Acetate | D2: Ketone bodies | E2: Ketone bodies | F2: Acetate (mmol/l) | G2: Acetate
A3: =_xlfn.CONCAT("metab_", $B3) -> metab_acetoacetate | B3: acetoacetate | C3: Acetoacetate | D3: Ketone bodies | E3: Ketone bodies | F3: Acetoacetate (mmol/l) | G3: Acetoacetate
A4: =_xlfn.CONCAT("metab_", $B4) -> metab_acetone | B4: acetone | C4: Acetone | D4: Ketone bodies | E4: Ketone bodies | F4: Acetone (mmol/l) | G4: Acetone
A5: =_xlfn.CONCAT("metab_", $B5) -> metab_ala | B5: ala | C5: Alanine (mmol/l) | D5: Amino acids | E5: Amino acids | F5: Alanine (mmol/l) | G5: Alanine
A6: =_xlfn.CONCAT("metab_", $B6) -> metab_albumin | B6: albumin | C6: Albumin | D6: Fluid balance | E6: Fluid balance | F6: Albumin (g/l) | G6: Albumin
A7: =_xlfn.CONCAT("metab_", $B7) -> metab_apoa1 | B7: apoa1 | C7: Apolipoprotein A-I (g/l) | D7: Apolipoproteins | E7: Apolipoproteins | F7: Apolipoprotein A-I (g/l) | G7: Apolipoprotein A-I
A8: =_xlfn.CONCAT("metab_", $B8) -> metab_apob | B8: apob | C8: Apolipoprotein B (g/l) | D8: Apolipoproteins | E8: Apolipoproteins | F8: Apolipoprotein B (g/l) | G8: Apolipoprotein B
A9: =_xlfn.CONCAT("metab_", $B9) -> metab_apobapoa1 | B9: apobapoa1 | C9: Ratio of apolipoprotein B to apolipoprotein A-I | D9: Apolipoproteins | E9: Apolipoproteins | F9: Apolipoprotein B/A-I (g/l) | G9: Apolipoprotein B/A-I
A10: =_xlfn.CONCAT("metab_", $B10) -> metab_bohbutyrate | B10: bohbutyrate | C10: bOHbutyrate | D10: Ketone bodies | E10: Ketone bodies | F10: 3-Hydroxybutyrate (mmol/l) | G10: 3-Hydroxybutyrate
A11: =_xlfn.CONCAT("metab_", $B11) -> metab_cholines | B11: cholines | C11: Cholines | D11: Other lipids | E11: Other lipids | F11: Total cholines (mmol/l) | G11: Total cholines
A12: =_xlfn.CONCAT("metab_", $B12) -> metab_citrate | B12: citrate | C12: Citrate | D12: Glycolysis related metabolites | E12: Glycolysis related metabolites | F12: Citrate (mmol/l) | G12: Citrate
A13: =_xlfn.CONCAT("metab_", $B13) -> metab_clinicalldlc | B13: clinicalldlc | C13: Clinical LDL-C | D13: Cholesterol | E13: Cholesterol | F13: Clinical LDL cholesterol (mmol/l) | G13: Clinical LDL cholesterol
... A251: =_xlfn.CONCAT("metab_", $B251) -> metab_xxlvldltgpct | B251: xxlvldltgpct | C251: Triglycerides in chylomicrons and extremely large VLDL to total lipids in chylomicrons and extremely large VLDL ratio (%) | D251: Lipoprotein subclasses ratios | E251: Extremely large VLDL ratios | F251: Triglycerides (mmol/l) | G251: Ratio

Sheet direct_metabolon
A1: id | B1: compid_to_match | C1: pathway.sortorder | D1: biochemical | E1: SUPER_PATHWAY | F1: sub.pathway | G1: comp.id | H1: platform | I1: chemical.id | J1: ri | K1: mass | L1: cas | M1: pubchem | N1: kegg | O1: hmdb | P1: feature_names
A2: =_xlfn.CONCAT("metab_compid_", $G2) -> metab_compid_57814 | B2: compid57814 | C2: 426 | D2: (N(1) + N(8))-acetylspermidine | E2: Amino Acid | F2: Polyamine Metabolism | G2: 57814 | H2: posearly | I2: 100016038 | J2: 3080 | K2: 188.17574 | L2: NA | M2: NA | N2: NA | O2: NA | P2: compid57814
A3: =_xlfn.CONCAT("metab_compid_", $G3) -> metab_compid_52603 | B3: compid52603 | C3: 1852 | D3: 1,2-dilinoleoyl-GPC (18:2/18:2) | E3: Lipid | F3: Phosphatidylcholine (PC) | G3: 52603 | H3: poslate | I3: 100008903 | J3: 2006 | K3: 782.56944 | L3: 998-06-1 | M3: 5288075 | N3: NA | O3: HMDB08138 | P3: compid52603
A4: =_xlfn.CONCAT("metab_compid_", $G4) -> metab_compid_19130 | B4: compid19130 | C4: 1778 | D4: 1,2-dipalmitoyl-GPC (16:0/16:0) | E4: Lipid | F4: Phosphatidylcholine (PC) | G4: 19130 | H4: poslate | I4: 100000657 | J4: 2365 | K4: 734.56944 | L4: 63-89-8 | M4: 452110 | N4: NA | O4: HMDB00564 | P4: compid19130
A5: =_xlfn.CONCAT("metab_compid_", $G5) -> metab_compid_20675 | B5: compid20675 | C5: 926 | D5: 1,5-anhydroglucitol (1,5-AG) | E5: Carbohydrate | F5: Glycolysis, Gluconeogenesis, and Pyruvate Metabolism | G5: 20675 | H5: neg | I5: 100000580 | J5: 802 | K5: 163.06119 | L5: 154-58-5 | M5: 64960 | N5: C07326 | O5: HMDB02712 | P5: compid20675
A6: =_xlfn.CONCAT("metab_compid_", $G6) -> metab_compid_44621 | B6: compid44621 | C6: 2282 | D6: 1-(1-enyl-oleoyl)-GPE (P-18:1)* | E6: Lipid | F6: Lysoplasmalogen | G6: 44621 | H6: poslate | I6: 100005372 | J6: 1566 | K6: 464.3136 | L6: NA | M6: NA | N6: NA | O6: NA | P6: compid44621
A7: =_xlfn.CONCAT("metab_compid_", $G7) -> metab_compid_52689 | B7: compid52689 | C7: 2260 | D7: 1-(1-enyl-palmitoyl)-2-arachidonoyl-GPC (P-16:0/20:4)* | E7: Lipid | F7: Plasmalogen | G7: 52689 | H7: poslate | I7: 100009014 | J7: 2154 | K7: 766.57452 | L7: NA | M7: NA | N7: NA | O7: HMDB11220 | P7: compid52689
A8: =_xlfn.CONCAT("metab_compid_", $G8) -> metab_compid_52673 | B8: compid52673 | C8: 2252 | D8: 1-(1-enyl-palmitoyl)-2-arachidonoyl-GPE (P-16:0/20:4)* | E8: Lipid | F8: Plasmalogen | G8: 52673 | H8: poslate | I8: 100009002 | J8: 2270 | K8: 724.52757 | L8: NA | M8: NA | N8: NA | O8: HMDB11352 | P8: compid52673
A9: =_xlfn.CONCAT("metab_compid_", $G9) -> metab_compid_52682 | B9: compid52682 | C9: 2261 | D9: 1-(1-enyl-palmitoyl)-2-linoleoyl-GPC (P-16:0/18:2)* | E9: Lipid | F9: Plasmalogen | G9: 52682 | H9: poslate | I9: 100009009 | J9: 2226 | K9: 742.57452 | L9: NA | M9: NA | N9: NA | O9: HMDB11211 | P9: compid52682
A10: =_xlfn.CONCAT("metab_compid_", $G10) -> metab_compid_52677 | B10: compid52677 | C10: 2249 | D10: 1-(1-enyl-palmitoyl)-2-linoleoyl-GPE (P-16:0/18:2)* | E10: Lipid | F10: Plasmalogen | G10: 52677 | H10: poslate | I10: 100009069 | J10: 2351 | K10: 700.52757 | L10: NA | M10: NA | N10: NA | O10: HMDB11343 | P10: compid52677
A11: =_xlfn.CONCAT("metab_compid_", $G11) -> metab_compid_52478 | B11: compid52478 | C11: 2254 | D11: 1-(1-enyl-palmitoyl)-2-oleoyl-GPC (P-16:0/18:1)* | E11: Lipid | F11: Plasmalogen | G11: 52478 | H11: poslate | I11: 100009007 | J11: 2443 | K11: 744.59017 | L11: NA | M11: NA | N11: NA | O11: NA | P11: compid52478
A12: =_xlfn.CONCAT("metab_compid_", $G12) -> metab_compid_52477 | B12: compid52477 | C12: 2248 | D12: 1-(1-enyl-palmitoyl)-2-oleoyl-GPE (P-16:0/18:1)* | E12: Lipid | F12: Plasmalogen | G12: 52477 | H12: poslate | I12: 100009005 | J12: 2600 | K12: 702.54322 | L12: NA | M12: NA | N12: NA | O12: HMDB11342 | P12: compid52477
A13: =_xlfn.CONCAT("metab_compid_", $G13) -> metab_compid_52713 | B13: compid52713 | C13: 2251 | D13: 1-(1-enyl-palmitoyl)-2-palmitoleoyl-GPC (P-16:0/16:1)* | E13: Lipid | F13: Plasmalogen | G13: 52713 | H13: poslate | I13: 100009160 | J13: 2218 | K13: 716.55887 | L13: NA | M13: NA | N13: NA | O13: HMDB11207 | P13: compid52713
A14: =_xlfn.CONCAT("metab_compid_", $G14) -> metab_compid_52716 | B14: compid52716 | C14: 2250 | D14: 1-(1-enyl-palmitoyl)-2-palmitoyl-GPC (P-16:0/16:0)* | E14: Lipid | F14: Plasmalogen | G14: 52716 | H14: poslate | I14: 100009162 | J14: 2454 | K14: 718.57452 | L14: NA | M14: 11146967 | N14: NA | O14: HMDB11206 | P14: compid52716
A15: =_xlfn.CONCAT("metab_compid_", $G15) -> metab_compid_52474 | B15: compid52474 | C15: 2279 | D15: 1-(1-enyl-palmitoyl)-GPC (P-16:0)* | E15: Lipid | F15: Lysoplasmalogen | G15: 52474 | H15: poslate | I15: 100002875 | J15: 1547 | K15: 480.34485 | L15: NA | M15: 10917802 | N15: NA | O15: HMDB10407 | P15: compid52474
A16: =_xlfn.CONCAT("metab_compid_", $G16) -> metab_compid_39270 | B16: compid39270 | C16: 2280 | D16: 1-(1-enyl-palmitoyl)-GPE (P-16:0)* | E16: Lipid | F16: Lysoplasmalogen | G16: 39270 | H16: poslate | I16: 100003000 | J16: 1558 | K16: 438.2979 | L16: NA | M16: NA | N16: NA | O16: NA | P16: compid39270
A17: =_xlfn.CONCAT("metab_compid_", $G17) -> metab_compid_52475 | B17: compid52475 | C17: 2265 | D17: 1-(1-enyl-stearoyl)-2-arachidonoyl-GPE (P-18:0/20:4)* | E17: Lipid | F17: Plasmalogen | G17: 52475 | H17: poslate | I17: 100008999 | J17: 2511 | K17: 752.55887 | L17: NA | M17: 9547058 | N17: NA | O17: HMDB05779 | P17: compid52475
A18: =_xlfn.CONCAT("metab_compid_", $G18) -> metab_compid_52748 | B18: compid52748 | C18: 2257 | D18: 1-(1-enyl-stearoyl)-2-linoleoyl-GPE (P-18:0/18:2)* | E18: Lipid | F18: Plasmalogen | G18: 52748 | H18: poslate | I18: 100009225 | J18: 2633 | K18: 728.55887 | L18: NA | M18: NA | N18: NA | O18: HMDB11376 | P18: compid52748
A19: =_xlfn.CONCAT("metab_compid_", $G19) -> metab_compid_52614 | B19: compid52614 | C19: 2256 | D19: 1-(1-enyl-stearoyl)-2-oleoyl-GPE (P-18:0/18:1) | E19: Lipid | F19: Plasmalogen | G19: 52614 | H19: poslate | I19: 100008919 | J19: 2950 | K19: 730.57452 | L19: 144371-68-6 | M19: NA | N19: NA | O19: HMDB11375 | P19: compid52614
A20: =_xlfn.CONCAT("metab_compid_", $G20) -> metab_compid_39271 | B20: compid39271 | C20: 2284 | D20: 1-(1-enyl-stearoyl)-GPE (P-18:0)* | E20: Lipid | F20: Lysoplasmalogen | G20: 39271 | H20: poslate | I20: 100003001 | J20: 1649 | K20: 466.3292 | L20: NA | M20: NA | N20: NA | O20: NA | P20: compid39271
A21: =_xlfn.CONCAT("metab_compid_", $G21) -> metab_compid_46325 | B21: compid46325 | C21: 2046 | D21: 1-arachidonoyl-GPA (20:4) | E21: Lipid | F21: Lysophospholipid | G21: 46325 | H21: neg | I21: 100004442 | J21: 5499 | K21: 457.23606 | L21: 799268-65-8 | M21: NA | N21: NA | O21: NA | P21: compid46325
A22: =_xlfn.CONCAT("metab_compid_", $G22) -> metab_compid_33228 | B22: compid33228 | C22: 2083 | D22: 1-arachidonoyl-GPC (20:4n6)* | E22: Lipid | F22: Lysophospholipid | G22: 33228 | H22: poslate | I22: 100001551 | J22: 1460 | K22: 544.33977 | L22: NA | M22: NA | N22: C05208 | O22: HMDB10395 | P22: compid33228
A23: =_xlfn.CONCAT("metab_compid_", $G23) -> metab_compid_35186 | B23: compid35186 | C23: 2123 | D23: 1-arachidonoyl-GPE (20:4n6)* | E23: Lipid | F23: Lysophospholipid | G23: 35186 | H23: poslate | I23: 100001571 | J23: 1470 | K23: 502.29282 | L23: NA | M23: 42607465 | N23: NA | O23: HMDB11517 | P23: compid35186
A24: =_xlfn.CONCAT("metab_compid_", $G24) -> metab_compid_34214 | B24: compid34214 | C24: 2157 | D24: 1-arachidonoyl-GPI (20:4)* | E24: Lipid | F24: Lysophospholipid | G24: 34214 | H24: neg | I24: 100001654 | J24: 5482 | K24: 619.28888 | L24: NA | M24: NA | N24: NA | O24: HMDB61690 | P24: compid34214
A25: =_xlfn.CONCAT("metab_compid_", $G25) -> metab_compid_34397 | B25: compid34397 | C25: 2308 | D25: 1-arachidonylglycerol (20:4) | E25: Lipid | F25: Monoacylglycerol | G25: 34397 | H25: neg | I25: 100001433 | J25: 6250 | K25: 303.23293 | L25: 35474-99-8 | M25: 5282281 | N25: C13857 | O25: HMDB11549 | P25: compid34397
A26: =_xlfn.CONCAT("metab_compid_", $G26) -> metab_compid_64879 | B26: compid64879 | C26: 295 | D26: N-lactoyl isoleucine | E26: Amino Acid | F26: Leucine, Isoleucine and Valine Metabolism | G26: 64879 | H26: neg | I26: 100022479 | J26: 2628 | K26: 202.10848 | L26: 210769-85-0 | M26: 85541231 | N26: NA | O26: HMDB0062180 | P26: compid64879
A27: =_xlfn.CONCAT("metab_compid_", $G27) -> metab_compid_64880 | B27: compid64880 | C27: 259 | D27: N-lactoyl leucine | E27: Amino Acid | F27: Leucine, Isoleucine and Valine Metabolism | G27: 64880 | H27: neg | I27: 100022480 | J27: 2663 | K27: 202.10848 | L27: 210769-82-7 | M27: 57329455 | N27: NA | O27: HMDB0062176 | P27: compid64880
A28: =_xlfn.CONCAT("metab_compid_", $G28) -> metab_compid_64881 | B28: compid64881 | C28: 118 | D28: N-lactoyl phenylalanine | E28: Amino Acid | F28: Phenylalanine Metabolism | G28: 64881 | H28: neg | I28: 100022482 | J28: 2844 | K28: 236.09283 | L28: 183241-73-8 | M28: 11075454 | N28: NA | O28: HMDB0062175 | P28: compid64881
A29: =_xlfn.CONCAT("metab_compid_", $G29) -> metab_compid_64882 | B29: compid64882 | C29: 134 | D29: N-lactoyl tyrosine | E29: Amino Acid | F29: Tyrosine Metabolism | G29: 64882 | H29: neg | I29: 100022484 | J29: 1846 | K29: 252.08774 | L29: 1373771-50-6 | M29: 22167491 | N29: NA | O29: HMDB0062177 | P29: compid64882
A30: =_xlfn.CONCAT("metab_compid_", $G30) -> metab_compid_64883 | B30: compid64883 | C30: 316 | D30: N-lactoyl valine | E30: Amino Acid | F30: Leucine, Isoleucine and Valine Metabolism | G30: 64883 | H30: neg | I30: 100022485 | J30: 2008 | K30: 188.09283 | L30: 21753-44-6 | M30: 131770417 | N30: NA | O30: HMDB0062181 | P30: compid64883
A31: =_xlfn.CONCAT("metab_compid_", $G31) -> metab_compid_48341 | B31: compid48341 | C31: 2307 | D31: 1-dihomo-linolenylglycerol (20:3) | E31: Lipid | F31: Monoacylglycerol | G31: 48341 | H31: neg | I31: 100006121 | J31: 6400 | K31: 305.24858 | L31: NA | M31: NA | N31: NA | O31: NA | P31: compid48341
A32: =_xlfn.CONCAT("metab_compid_", $G32) -> metab_compid_35153 | B32: compid35153 | C32: 2311 | D32: 1-docosahexaenoylglycerol (22:6) | E32: Lipid | F32: Monoacylglycerol | G32: 35153 | H32: neg | I32: 100001481 | J32: 6150 | K32: 309.22236 | L32: NA | M32: NA | N32: NA | O32: HMDB11587 | P32: compid35153
A33: =_xlfn.CONCAT("metab_compid_", $G33) -> metab_compid_45951 | B33: compid45951 | C33: 2068 | D33: 1-linolenoyl-GPC (18:3)* | E33: Lipid | F33: Lysophospholipid | G33: 45951 | H33: poslate | I33: 100005350 | J33: 1410 | K33: 518.32412 | L33: NA | M33: NA | N33: NA | O33: HMDB10388 | P33: compid45951
A34: =_xlfn.CONCAT("metab_compid_", $G34) -> metab_compid_34393 | B34: compid34393 | C34: 2303 | D34: 1-linolenoylglycerol (18:3) | E34: Lipid | F34: Monoacylglycerol | G34: 34393 | H34: neg | I34: 100001435 | J34: 6214 | K34: 277.21728 | L34: 124151-74-2 | M34: 53480978 | N34: NA | O34: HMDB11569 | P34: compid34393
A35: =_xlfn.CONCAT("metab_compid_", $G35) -> metab_compid_52710 | B35: compid52710 | C35: 1856 | D35: 1-linoleoyl-2-arachidonoyl-GPC (18:2/20:4n6)* | E35: Lipid | F35: Phosphatidylcholine (PC) | G35: 52710 | H35: poslate | I35: 100009131 | J35: 1969 | K35: 806.56944 | L35: NA | M35: NA | N35: NA | O35: HMDB08147 | P35: compid52710
A36: =_xlfn.CONCAT("metab_compid_", $G36) -> metab_compid_53176 | B36: compid53176 | C36: 1853 | D36: 1-linoleoyl-2-linolenoyl-GPC (18:2/18:3)* | E36: Lipid | F36: Phosphatidylcholine (PC) | G36: 53176 | H36: poslate | I36: 100009343 | J36: 1939 | K36: 780.55378 | L36: NA | M36: NA | N36: NA | O36: HMDB08141 | P36: compid53176
A37: =_xlfn.CONCAT("metab_compid_", $G37) -> metab_compid_52690 | B37: compid52690 | C37: 2043 | D37: 1-linoleoyl-GPA (18:2)* | E37: Lipid | F37: Lysophospholipid | G37: 52690 | H37: poslate | I37: 100009082 | J37: 1550 | K37: 435.25062 | L37: NA | M37: NA | N37: NA | O37: HMDB07856 | P37: compid52690
A38: =_xlfn.CONCAT("metab_compid_", $G38) -> metab_compid_34419 | B38: compid34419 | C38: 2066 | D38: 1-linoleoyl-GPC (18:2) | E38: Lipid | F38: Lysophospholipid | G38: 34419 | H38: poslate | I38: 100001395 | J38: 1465 | K38: 520.33977 | L38: NA | M38: 11988421 | N38: C04100 | O38: HMDB10386 | P38: compid34419
A39: =_xlfn.CONCAT("metab_compid_", $G39) -> metab_compid_36600 | B39: compid36600 | C39: 2112 | D39: 1-linoleoyl-GPE (18:2)* | E39: Lipid | F39: Lysophospholipid | G39: 36600 | H39: poslate | I39: 100001570 | J39: 1482 | K39: 478.29282 | L39: NA | M39: 52925130 | N39: NA | O39: HMDB11507 | P39: compid36600
A40: =_xlfn.CONCAT("metab_compid_", $G40) -> metab_compid_54885 | B40: compid54885 | C40: 2145 | D40: 1-linoleoyl-GPG (18:2)* | E40: Lipid | F40: Lysophospholipid | G40: 54885 | H40: neg | I40: 100009227 | J40: 5516 | K40: 507.27284 | L40: NA | M40: NA | N40: NA | O40: NA | P40: compid54885
...

Sheet direct_nightingale
A1: id | B1: Row.names | C1: Excel.column.name | D1: CSV.column.name | E1: Biomarker.name | F1: Unit | G1: Group | H1: Subgroup
A2: =_xlfn.CONCAT("metab_", $B2) -> metab_hdlsize | B2: hdlsize | C2: HDL size | D2: HDL_size | E2: Average diameter for HDL particles | F2: nm | G2: Lipoprotein particle sizes
